Workbook

Sheet Employee_Master
A1: Employee_ID | B1: Employee_Name | C1: Department | D1: House | E1: Employee_ID
A2: 450230 | B2: Aarti Gupta | C2: QA | D2: Agility | E2: 450230
A3: 452073 | B3: Aashish | C3: EB | D3: Innovation | E3: 452073
A4: 461161 | B4: Abhay Singh | C4: Packing | D4: Vibrancy | E4: 461161
A5: 456091 | B5: Abhinesh Pandey | C5: EHS | D5: Agility | E5: 456091
A6: 478308 | B6: Abhishek savita | C6: EB | D6: Care | E6: 478308
A7: 478266 | B7: Abhishek Sharma | C7: QA | D7: Vibrancy | E7: 478266
A8: 466167 | B8: Aishwarya Sharma | C8: QA | D8: Vibrancy | E8: 466167
A9: 712428 | B9: Akanksha Gangwar | C9: Engineering | D9: Care | E9: 712428
A10: 454456 | B10: Akash Deshmukh | C10: WPB | D10: Vibrancy | E10: 454456
A11: 724729 | B11: Akash Kumar | C11: Engineering | D11: Innovation | E11: 724729
A12: 452119 | B12: Akhil Tiwari | C12: EB | D12: Vibrancy | E12: 452119
A13: 430977 | B13: Akshit Sood | C13: Finance & Stores | D13: Courage | E13: 430977
... A170: 460888 | B170: Yatin | C170: Materials | D170: Agility | E170: 460888
A171: 726299 | B171: =_xlfn.XLOOKUP(A171,[1]Attendance!$B$2:$B$167,[1]Attendance!$C$2:$C$167,0) -> Anu Devi | C171: Production | D171: Courage | E171: 726299
A172: 728885 | B172: Simran | C172: Production | D172: Courage | E172: 728885
A173: 728886 | B173: Annu | C173: Production | D173: Care | E173: 728886
A174: 728833 | B174: Mo. Azhar Ansari | C174: Production | D174: Innovation | E174: 728833
A175: 728772 | B175: Abhishek Dixit | C175: Production | D175: Care | E175: 728772
A176: 729134 | B176: Gursimrat Singh | C176: Materials | D176: Innovation | E176: 729134
A177: 728844 | B177: Simarpreet | C177: Materials | D177: Vibrancy | E177: 728844
A178: 728947 | B178: Salja | C178: Materials | D178: Agility | E178: 728947
A179: 728849 | B179: Rohit Kumar | C179: Production | D179: Vibrancy | E179: 728849
A180: 729000 | B180: Nitish kumar | C180: Materials | D180: Innovation | E180: 729000
A181: 729581 | B181: Ajay Kumar Yadav | C181: QA | D181: Innovation | E181: 729581
A182: 730033 | B182: Ankush Jain | C182: Finance & Stores | D182: Vibrancy | E182: 730033
A183: 732529 | B183: Niyati Dimri | C183: Engineering | D183: Courage | E183: 732529
A184: 733893 | B184: Gaurav Kumar | C184: Materials | D184: Innovation | E184: 733893
A185: 733466 | B185: Vikas | C185: Finance & Stores | E185: 733466

Sheet Event_Master
A1: Event_ID | B1: Event_Name | C1: Type | D1: Difficulty_Level (Casual/Medium/High) | E1: Multiplier
A2: 1 | B2: Carrom | C2: Indoor | D2: Casual | E2: 1
A3: 2 | B3: Chess | C3: Indoor | D3: Medium | E3: 1.3
A4: 3 | B4: Fuseball | C4: Indoor | D4: Casual | E4: 1
A5: 4 | B5: Air Hockey | C5: Indoor | D5: Casual | E5: 1
A6: 5 | B6: Table tennis | C6: Indoor | D6: Medium | E6: 1.5
A7: 6 | B7: Badminton Men singles | C7: Indoor | D7: Medium | E7: 1.5
A8: 7 | B8: Cricket | C8: Outdoor | D8: High | E8: 1.5
A9: 8 | B9: Vollyball | C9: Outdoor | D9: High | E9: 1.5
A10: 9 | B10: Basket Ball | C10: Outdoor | D10: High | E10: 1.5
A11: 10 | B11: Walk | C11: Outdoor | D11: Medium | E11: 1
A12: 11 | B12: Running | C12: Outdoor | D12: Medium | E12: 1.5
A13: 12 | B13: Relay | C13: Outdoor | D13: High | E13: 2
B14: Fuseball Double | C14: Indoor | D14: Casual | E14: 1
B15: Table tennis Double | C15: Indoor | D15: Medium | E15: 1.5
B16: Badminton Men Doubles | C16: Indoor | D16: Medium | E16: 1.5
B17: Skipping | C17: Indoor | D17: Casual | E17: 1
B18: Badminton Mix Doubles | C18: Indoor | D18: Medium | E18: 1.5
B19: Badminton Women singles | C19: Indoor | D19: Medium | E19: 1.5
B20: Badminton | C20: Indoor | D20: Medium | E20: 1.5

Sheet Score_Table
B3: Position
B4: Winner
B5: Runner-up
B6: 2nd Runner-up
B7: Semi
B8: Quarter

Sheet Participation_Entry
A1: Date | B1: Employee_ID | C1: Employee_Name | D1: Event | E1: Registered (Yes/No) | F1: Participated (Yes/No) | G1: Position (Winner/Runner-up/2nd Runner-up/Semi/Quarter/Participant) | H1: Participation_Points | I1: Base_Points | J1: Multiplier | K1: Game_ Points | L1: Final_Event_Points
A2: 46026 | B2: 365114 | C2: =VLOOKUP(B2,Employee_Master!A:B,2,0) -> Bhanu Sirohi | D2: Walk | E2: YES | F2: YES | H2: 70.777 | I2: =IF(G2="Winner",100,IF(G2="Runner-up",70,IF(G2="2nd Runner-up",50,IF(G2="Semi",30,IF(G2="Quarter",20,0))))) -> 0 | J2: =IFERROR(VLOOKUP(D2,Event_Master!B:E,4,FALSE),1) -> 1 | K2: =(I2*J2) -> 0 | L2: =K2+H2 -> 70.777
A3: 46026 | B3: 396485 | C3: =VLOOKUP(B3,Employee_Master!A:B,2,0) -> Khushbir Singh | D3: Walk | E3: YES | F3: YES | H3: 52.1576 | I3: =IF(G3="Winner",100,IF(G3="Runner-up",70,IF(G3="2nd Runner-up",50,IF(G3="Semi",30,IF(G3="Quarter",20,0))))) -> 0 | J3: =IFERROR(VLOOKUP(D3,Event_Master!B:E,4,FALSE),1) -> 1 | K3: =(I3*J3) -> 0 | L3: =K3+H3 -> 52.1576
A4: 46026 | B4: 412273 | C4: =VLOOKUP(B4,Employee_Master!A:B,2,0) -> Sandeep Sengar | D4: Walk | E4: YES | F4: YES | H4: 11.3269 | I4: =IF(G4="Winner",100,IF(G4="Runner-up",70,IF(G4="2nd Runner-up",50,IF(G4="Semi",30,IF(G4="Quarter",20,0))))) -> 0 | J4: =IFERROR(VLOOKUP(D4,Event_Master!B:E,4,FALSE),1) -> 1 | K4: =(I4*J4) -> 0 | L4: =K4+H4 -> 11.3269
A5: 46026 | B5: 416828 | C5: =VLOOKUP(B5,Employee_Master!A:B,2,0) -> Keshav Dev | D5: Walk | E5: YES | F5: YES | H5: 41.5951 | I5: =IF(G5="Winner",100,IF(G5="Runner-up",70,IF(G5="2nd Runner-up",50,IF(G5="Semi",30,IF(G5="Quarter",20,0))))) -> 0 | J5: =IFERROR(VLOOKUP(D5,Event_Master!B:E,4,FALSE),1) -> 1 | K5: =(I5*J5) -> 0 | L5: =K5+H5 -> 41.5951
A6: 46026 | B6: 420109 | C6: =VLOOKUP(B6,Employee_Master!A:B,2,0) -> Chandraprakash Nandwana | D6: Walk | E6: YES | F6: YES | H6: 26.036 | I6: =IF(G6="Winner",100,IF(G6="Runner-up",70,IF(G6="2nd Runner-up",50,IF(G6="Semi",30,IF(G6="Quarter",20,0))))) -> 0 | J6: =IFERROR(VLOOKUP(D6,Event_Master!B:E,4,FALSE),1) -> 1 | K6: =(I6*J6) -> 0 | L6: =K6+H6 -> 26.036
A7: 46026 | B7: 424332 | C7: =VLOOKUP(B7,Employee_Master!A:B,2,0) -> Naresh Kumar | D7: Walk | E7: YES | F7: YES | H7: 30.8046 | I7: =IF(G7="Winner",100,IF(G7="Runner-up",70,IF(G7="2nd Runner-up",50,IF(G7="Semi",30,IF(G7="Quarter",20,0))))) -> 0 | J7: =IFERROR(VLOOKUP(D7,Event_Master!B:E,4,FALSE),1) -> 1 | K7: =(I7*J7) -> 0 | L7: =K7+H7 -> 30.8046
A8: 46026 | B8: 426232 | C8: =VLOOKUP(B8,Employee_Master!A:B,2,0) -> Varish Hussain | D8: Walk | E8: YES | F8: YES | H8: 17.8847 | I8: =IF(G8="Winner",100,IF(G8="Runner-up",70,IF(G8="2nd Runner-up",50,IF(G8="Semi",30,IF(G8="Quarter",20,0))))) -> 0 | J8: =IFERROR(VLOOKUP(D8,Event_Master!B:E,4,FALSE),1) -> 1 | K8: =(I8*J8) -> 0 | L8: =K8+H8 -> 17.8847
A9: 46026 | B9: 427154 | C9: =VLOOKUP(B9,Employee_Master!A:B,2,0) -> Rohan Mehra | D9: Walk | E9: YES | F9: YES | H9: 4.6855 | I9: =IF(G9="Winner",100,IF(G9="Runner-up",70,IF(G9="2nd Runner-up",50,IF(G9="Semi",30,IF(G9="Quarter",20,0))))) -> 0 | J9: =IFERROR(VLOOKUP(D9,Event_Master!B:E,4,FALSE),1) -> 1 | K9: =(I9*J9) -> 0 | L9: =K9+H9 -> 4.6855
A10: 46026 | B10: 427568 | C10: =VLOOKUP(B10,Employee_Master!A:B,2,0) -> Anjali Sundrani | D10: Walk | E10: YES | F10: YES | H10: 3.9742 | I10: =IF(G10="Winner",100,IF(G10="Runner-up",70,IF(G10="2nd Runner-up",50,IF(G10="Semi",30,IF(G10="Quarter",20,0))))) -> 0 | J10: =IFERROR(VLOOKUP(D10,Event_Master!B:E,4,FALSE),1) -> 1 | K10: =(I10*J10) -> 0 | L10: =K10+H10 -> 3.9742
A11: 46026 | B11: 428544 | C11: =VLOOKUP(B11,Employee_Master!A:B,2,0) -> Harjot Singh | D11: Walk | E11: YES | F11: YES | H11: 12.429 | I11: =IF(G11="Winner",100,IF(G11="Runner-up",70,IF(G11="2nd Runner-up",50,IF(G11="Semi",30,IF(G11="Quarter",20,0))))) -> 0 | J11: =IFERROR(VLOOKUP(D11,Event_Master!B:E,4,FALSE),1) -> 1 | K11: =(I11*J11) -> 0 | L11: =K11+H11 -> 12.429
A12: 46026 | B12: 430977 | C12: =VLOOKUP(B12,Employee_Master!A:B,2,0) -> Akshit Sood | D12: Walk | E12: YES | F12: YES | H12: 23.6 | I12: =IF(G12="Winner",100,IF(G12="Runner-up",70,IF(G12="2nd Runner-up",50,IF(G12="Semi",30,IF(G12="Quarter",20,0))))) -> 0 | J12: =IFERROR(VLOOKUP(D12,Event_Master!B:E,4,FALSE),1) -> 1 | K12: =(I12*J12) -> 0 | L12: =K12+H12 -> 23.6
A13: 46026 | B13: 432865 | C13: =VLOOKUP(B13,Employee_Master!A:B,2,0) -> Rupesh Gandhi | D13: Walk | E13: YES | F13: YES | H13: 22.3166 | I13: =IF(G13="Winner",100,IF(G13="Runner-up",70,IF(G13="2nd Runner-up",50,IF(G13="Semi",30,IF(G13="Quarter",20,0))))) -> 0 | J13: =IFERROR(VLOOKUP(D13,Event_Master!B:E,4,FALSE),1) -> 1 | K13: =(I13*J13) -> 0 | L13: =K13+H13 -> 22.3166
... A102: 46026 | B102: 722393 | C102: =VLOOKUP(B102,Employee_Master!A:B,2,0) -> Koteswara Devireddy | D102: Walk | E102: YES | F102: YES | H102: 35.2506 | I102: =IF(G102="Winner",100,IF(G102="Runner-up",70,IF(G102="2nd Runner-up",50,IF(G102="Semi",30,IF(G102="Quarter",20,0))))) -> 0 | J102: =IFERROR(VLOOKUP(D102,Event_Master!B:E,4,FALSE),1) -> 1 | K102: =(I102*J102) -> 0 | L102: =K102+H102 -> 35.2506
A103: 46360 | B103: 450230 | C103: =VLOOKUP(B103,Employee_Master!A:B,2,0) -> Aarti Gupta | D103: Skipping | E103: YES | F103: YES | H103: =IF(F103="Yes",10,0) -> 10 | I103: =IF(G103="Winner",100,IF(G103="Runner-up",70,IF(G103="2nd Runner-up",50,IF(G103="Semi",30,IF(G103="Quarter",20,0))))) -> 0 | J103: =IFERROR(VLOOKUP(D103,Event_Master!B:E,4,FALSE),1) -> 1 | K103: =(I103*J103) -> 0 | L103: =K103+H103 -> 10
A104: 46360 | B104: 478308 | C104: =VLOOKUP(B104,Employee_Master!A:B,2,0) -> Abhishek savita | D104: Skipping | E104: YES | F104: YES | H104: =IF(F104="Yes",10,0) -> 10 | I104: =IF(G104="Winner",100,IF(G104="Runner-up",70,IF(G104="2nd Runner-up",50,IF(G104="Semi",30,IF(G104="Quarter",20,0))))) -> 0 | J104: =IFERROR(VLOOKUP(D104,Event_Master!B:E,4,FALSE),1) -> 1 | K104: =(I104*J104) -> 0 | L104: =K104+H104 -> 10
A105: 46360 | B105: 466167 | C105: =VLOOKUP(B105,Employee_Master!A:B,2,0) -> Aishwarya Sharma | D105: Skipping | E105: YES | F105: YES | H105: =IF(F105="Yes",10,0) -> 10 | I105: =IF(G105="Winner",100,IF(G105="Runner-up",70,IF(G105="2nd Runner-up",50,IF(G105="Semi",30,IF(G105="Quarter",20,0))))) -> 0 | J105: =IFERROR(VLOOKUP(D105,Event_Master!B:E,4,FALSE),1) -> 1 | K105: =(I105*J105) -> 0 | L105: =K105+H105 -> 10
A106: 46360 | B106: 454456 | C106: =VLOOKUP(B106,Employee_Master!A:B,2,0) -> Akash Deshmukh | D106: Skipping | E106: YES | F106: YES | H106: =IF(F106="Yes",10,0) -> 10 | I106: =IF(G106="Winner",100,IF(G106="Runner-up",70,IF(G106="2nd Runner-up",50,IF(G106="Semi",30,IF(G106="Quarter",20,0))))) -> 0 | J106: =IFERROR(VLOOKUP(D106,Event_Master!B:E,4,FALSE),1) -> 1 | K106: =(I106*J106) -> 0 | L106: =K106+H106 -> 10
A107: 46360 | B107: 722783 | C107: =VLOOKUP(B107,Employee_Master!A:B,2,0) -> Anjali | D107: Skipping | E107: YES | F107: YES | H107: =IF(F107="Yes",10,0) -> 10 | I107: =IF(G107="Winner",100,IF(G107="Runner-up",70,IF(G107="2nd Runner-up",50,IF(G107="Semi",30,IF(G107="Quarter",20,0))))) -> 0 | J107: =IFERROR(VLOOKUP(D107,Event_Master!B:E,4,FALSE),1) -> 1 | K107: =(I107*J107) -> 0 | L107: =K107+H107 -> 10
A108: 46360 | B108: 469899 | C108: =VLOOKUP(B108,Employee_Master!A:B,2,0) -> Ankit | D108: Skipping | E108: YES | F108: YES | H108: =IF(F108="Yes",10,0) -> 10 | I108: =IF(G108="Winner",100,IF(G108="Runner-up",70,IF(G108="2nd Runner-up",50,IF(G108="Semi",30,IF(G108="Quarter",20,0))))) -> 0 | J108: =IFERROR(VLOOKUP(D108,Event_Master!B:E,4,FALSE),1) -> 1 | K108: =(I108*J108) -> 0 | L108: =K108+H108 -> 10
A109: 46360 | B109: 486309 | C109: =VLOOKUP(B109,Employee_Master!A:B,2,0) -> Ankit Bhatt | D109: Skipping | E109: YES | F109: YES | H109: =IF(F109="Yes",10,0) -> 10 | I109: =IF(G109="Winner",100,IF(G109="Runner-up",70,IF(G109="2nd Runner-up",50,IF(G109="Semi",30,IF(G109="Quarter",20,0))))) -> 0 | J109: =IFERROR(VLOOKUP(D109,Event_Master!B:E,4,FALSE),1) -> 1 | K109: =(I109*J109) -> 0 | L109: =K109+H109 -> 10
A110: 46360 | B110: 468157 | C110: =VLOOKUP(B110,Employee_Master!A:B,2,0) -> Ankit Tiwari | D110: Skipping | E110: YES | F110: YES | H110: =IF(F110="Yes",10,0) -> 10 | I110: =IF(G110="Winner",100,IF(G110="Runner-up",70,IF(G110="2nd Runner-up",50,IF(G110="Semi",30,IF(G110="Quarter",20,0))))) -> 0 | J110: =IFERROR(VLOOKUP(D110,Event_Master!B:E,4,FALSE),1) -> 1 | K110: =(I110*J110) -> 0 | L110: =K110+H110 -> 10
A111: 46360 | B111: 467068 | C111: =VLOOKUP(B111,Employee_Master!A:B,2,0) -> Anuj Kumar | D111: Skipping | E111: YES | F111: YES | H111: =IF(F111="Yes",10,0) -> 10 | I111: =IF(G111="Winner",100,IF(G111="Runner-up",70,IF(G111="2nd Runner-up",50,IF(G111="Semi",30,IF(G111="Quarter",20,0))))) -> 0 | J111: =IFERROR(VLOOKUP(D111,Event_Master!B:E,4,FALSE),1) -> 1 | K111: =(I111*J111) -> 0 | L111: =K111+H111 -> 10
A112: 46360 | B112: 466367 | C112: =VLOOKUP(B112,Employee_Master!A:B,2,0) -> Arjun Sharma | D112: Skipping | E112: YES | F112: YES | H112: =IF(F112="Yes",10,0) -> 10 | I112: =IF(G112="Winner",100,IF(G112="Runner-up",70,IF(G112="2nd Runner-up",50,IF(G112="Semi",30,IF(G112="Quarter",20,0))))) -> 0 | J112: =IFERROR(VLOOKUP(D112,Event_Master!B:E,4,FALSE),1) -> 1 | K112: =(I112*J112) -> 0 | L112: =K112+H112 -> 10
A113: 46360 | B113: 478084 | C113: =VLOOKUP(B113,Employee_Master!A:B,2,0) -> Ashish Mishra | D113: Skipping | E113: YES | F113: YES | H113: =IF(F113="Yes",10,0) -> 10 | I113: =IF(G113="Winner",100,IF(G113="Runner-up",70,IF(G113="2nd Runner-up",50,IF(G113="Semi",30,IF(G113="Quarter",20,0))))) -> 0 | J113: =IFERROR(VLOOKUP(D113,Event_Master!B:E,4,FALSE),1) -> 1 | K113: =(I113*J113) -> 0 | L113: =K113+H113 -> 10
A114: 46360 | B114: 452058 | C114: =VLOOKUP(B114,Employee_Master!A:B,2,0) -> Bhavya Gupta | D114: Skipping | E114: YES | F114: YES | H114: =IF(F114="Yes",10,0) -> 10 | I114: =IF(G114="Winner",100,IF(G114="Runner-up",70,IF(G114="2nd Runner-up",50,IF(G114="Semi",30,IF(G114="Quarter",20,0))))) -> 0 | J114: =IFERROR(VLOOKUP(D114,Event_Master!B:E,4,FALSE),1) -> 1 | K114: =(I114*J114) -> 0 | L114: =K114+H114 -> 10
... A159: 46360 | B159: 467519 | C159: =VLOOKUP(B159,Employee_Master!A:B,2,0) -> Vivek Tiwari | D159: Skipping | E159: YES | F159: YES | H159: =IF(F159="Yes",10,0) -> 10 | I159: =IF(G159="Winner",100,IF(G159="Runner-up",70,IF(G159="2nd Runner-up",50,IF(G159="Semi",30,IF(G159="Quarter",20,0))))) -> 0 | J159: =IFERROR(VLOOKUP(D159,Event_Master!B:E,4,FALSE),1) -> 1 | K159: =(I159*J159) -> 0 | L159: =K159+H159 -> 10
A160: 24-04-2026 | B160: 427154 | C160: =VLOOKUP(B160,Employee_Master!A:B,2,0) -> Rohan Mehra | D160: Badminton | E160: YES | F160: YES | H160: =IF(F160="Yes",10,0) -> 10 | I160: =IF(G160="Winner",100,IF(G160="Runner-up",70,IF(G160="2nd Runner-up",50,IF(G160="Semi",30,IF(G160="Quarter",20,0))))) -> 0 | J160: =IFERROR(VLOOKUP(D160,Event_Master!B:E,4,FALSE),1) -> 1.5 | K160: =(I160*J160) -> 0 | L160: =K160+H160 -> 10
A161: 24-04-2026 | B161: 452991 | C161: =VLOOKUP(B161,Employee_Master!A:B,2,0) -> Gourav Rohilla | D161: Badminton | E161: YES | F161: YES | H161: =IF(F161="Yes",10,0) -> 10 | I161: =IF(G161="Winner",100,IF(G161="Runner-up",70,IF(G161="2nd Runner-up",50,IF(G161="Semi",30,IF(G161="Quarter",20,0))))) -> 0 | J161: =IFERROR(VLOOKUP(D161,Event_Master!B:E,4,FALSE),1) -> 1.5 | K161: =(I161*J161) -> 0 | L161: =K161+H161 -> 10
A162: 24-04-2026 | B162: 432865 | C162: =VLOOKUP(B162,Employee_Master!A:B,2,0) -> Rupesh Gandhi | D162: Badminton | E162: YES | F162: YES | H162: =IF(F162="Yes",10,0) -> 10 | I162: =IF(G162="Winner",100,IF(G162="Runner-up",70,IF(G162="2nd Runner-up",50,IF(G162="Semi",30,IF(G162="Quarter",20,0))))) -> 0 | J162: =IFERROR(VLOOKUP(D162,Event_Master!B:E,4,FALSE),1) -> 1.5 | K162: =(I162*J162) -> 0 | L162: =K162+H162 -> 10
A163: 24-04-2026 | B163: 453089 | C163: =VLOOKUP(B163,Employee_Master!A:B,2,0) -> Arun Lamba | D163: Badminton | E163: YES | F163: YES | H163: =IF(F163="Yes",10,0) -> 10 | I163: =IF(G163="Winner",100,IF(G163="Runner-up",70,IF(G163="2nd Runner-up",50,IF(G163="Semi",30,IF(G163="Quarter",20,0))))) -> 0 | J163: =IFERROR(VLOOKUP(D163,Event_Master!B:E,4,FALSE),1) -> 1.5 | K163: =(I163*J163) -> 0 | L163: =K163+H163 -> 10
A164: 24-04-2026 | B164: 465255 | C164: =VLOOKUP(B164,Employee_Master!A:B,2,0) -> Mukul Suman | D164: Badminton | E164: YES | F164: YES | H164: =IF(F164="Yes",10,0) -> 10 | I164: =IF(G164="Winner",100,IF(G164="Runner-up",70,IF(G164="2nd Runner-up",50,IF(G164="Semi",30,IF(G164="Quarter",20,0))))) -> 0 | J164: =IFERROR(VLOOKUP(D164,Event_Master!B:E,4,FALSE),1) -> 1.5 | K164: =(I164*J164) -> 0 | L164: =K164+H164 -> 10
A165: 24-04-2026 | B165: 449551 | C165: =VLOOKUP(B165,Employee_Master!A:B,2,0) -> Ramesh Kumar | D165: Badminton | E165: YES | F165: YES | H165: =IF(F165="Yes",10,0) -> 10 | I165: =IF(G165="Winner",100,IF(G165="Runner-up",70,IF(G165="2nd Runner-up",50,IF(G165="Semi",30,IF(G165="Quarter",20,0))))) -> 0 | J165: =IFERROR(VLOOKUP(D165,Event_Master!B:E,4,FALSE),1) -> 1.5 | K165: =(I165*J165) -> 0 | L165: =K165+H165 -> 10
A166: 24-04-2026 | B166: 454456 | C166: =VLOOKUP(B166,Employee_Master!A:B,2,0) -> Akash Deshmukh | D166: Badminton | E166: YES | F166: YES | H166: =IF(F166="Yes",10,0) -> 10 | I166: =IF(G166="Winner",100,IF(G166="Runner-up",70,IF(G166="2nd Runner-up",50,IF(G166="Semi",30,IF(G166="Quarter",20,0))))) -> 0 | J166: =IFERROR(VLOOKUP(D166,Event_Master!B:E,4,FALSE),1) -> 1.5 | K166: =(I166*J166) -> 0 | L166: =K166+H166 -> 10
A167: 24-04-2026 | B167: 440620 | C167: =VLOOKUP(B167,Employee_Master!A:B,2,0) -> Kuldeep Singh | D167: Badminton | E167: YES | F167: YES | H167: =IF(F167="Yes",10,0) -> 10 | I167: =IF(G167="Winner",100,IF(G167="Runner-up",70,IF(G167="2nd Runner-up",50,IF(G167="Semi",30,IF(G167="Quarter",20,0))))) -> 0 | J167: =IFERROR(VLOOKUP(D167,Event_Master!B:E,4,FALSE),1) -> 1.5 | K167: =(I167*J167) -> 0 | L167: =K167+H167 -> 10
A168: 24-04-2026 | B168: 451567 | C168: =VLOOKUP(B168,Employee_Master!A:B,2,0) -> Gaurav Kumar | D168: Badminton | E168: YES | F168: YES | H168: =IF(F168="Yes",10,0) -> 10 | I168: =IF(G168="Winner",100,IF(G168="Runner-up",70,IF(G168="2nd Runner-up",50,IF(G168="Semi",30,IF(G168="Quarter",20,0))))) -> 0 | J168: =IFERROR(VLOOKUP(D168,Event_Master!B:E,4,FALSE),1) -> 1.5 | K168: =(I168*J168) -> 0 | L168: =K168+H168 -> 10
A169: 24-04-2026 | B169: 476372 | C169: =VLOOKUP(B169,Employee_Master!A:B,2,0) -> Laksh | D169: Badminton | E169: YES | F169: YES | H169: =IF(F169="Yes",10,0) -> 10 | I169: =IF(G169="Winner",100,IF(G169="Runner-up",70,IF(G169="2nd Runner-up",50,IF(G169="Semi",30,IF(G169="Quarter",20,0))))) -> 0 | J169: =IFERROR(VLOOKUP(D169,Event_Master!B:E,4,FALSE),1) -> 1.5 | K169: =(I169*J169) -> 0 | L169: =K169+H169 -> 10
A170: 24-04-2026 | B170: 466445 | C170: =VLOOKUP(B170,Employee_Master!A:B,2,0) -> Ayush Kumar | D170: Badminton | E170: YES | F170: YES | H170: =IF(F170="Yes",10,0) -> 10 | I170: =IF(G170="Winner",100,IF(G170="Runner-up",70,IF(G170="2nd Runner-up",50,IF(G170="Semi",30,IF(G170="Quarter",20,0))))) -> 0 | J170: =IFERROR(VLOOKUP(D170,Event_Master!B:E,4,FALSE),1) -> 1.5 | K170: =(I170*J170) -> 0 | L170: =K170+H170 -> 10
A171: 24-04-2026 | B171: 478084 | C171: =VLOOKUP(B171,Employee_Master!A:B,2,0) -> Ashish Mishra | D171: Badminton | E171: YES | F171: YES | H171: =IF(F171="Yes",10,0) -> 10 | I171: =IF(G171="Winner",100,IF(G171="Runner-up",70,IF(G171="2nd Runner-up",50,IF(G171="Semi",30,IF(G171="Quarter",20,0))))) -> 0 | J171: =IFERROR(VLOOKUP(D171,Event_Master!B:E,4,FALSE),1) -> 1.5 | K171: =(I171*J171) -> 0 | L171: =K171+H171 -> 10
... A178: 24-04-2026 | B178: 465254 | C178: =VLOOKUP(B178,Employee_Master!A:B,2,0) -> Narender Kumar | D178: Badminton | E178: YES | F178: YES | H178: =IF(F178="Yes",10,0) -> 10 | I178: =IF(G178="Winner",100,IF(G178="Runner-up",70,IF(G178="2nd Runner-up",50,IF(G178="Semi",30,IF(G178="Quarter",20,0))))) -> 0 | J178: =IFERROR(VLOOKUP(D178,Event_Master!B:E,4,FALSE),1) -> 1.5 | K178: =(I178*J178) -> 0 | L178: =K178+H178 -> 10
...

Sheet Sheet1
H1: Name | I1: Total Steps
H2: (712428)Akanksha Gangwar | I2: 212277 | J2: 21.2277
H3: Aarti Gupta | I3: 145900 | J3: 14.59
H4: Aashish Gupta | I4: 0 | J4: 0
H5: Abhay singh | I5: 67425 | J5: 6.7425
H6: Abhi | I6: 0 | J6: 0
H7: Abhi | I7: 0 | J7: 0
H8: Abhinesh Pandey | I8: 161479 | J8: 16.1479
H9: Abhishek Sharma | I9: 0 | J9: 0
H10: Aishwarya | I10: 357852 | J10: 35.7852
H11: Akash | I11: 340938 | J11: 34.0938
H12: Akash Kumar | I12: 385956 | J12: 38.5956
H13: Akhil Tiwari | I13: 255734 | J13: 25.5734
... H170: Yatin Saini | I170: 0 | J170: 0

Sheet Leaderboard
A1: Employee_ID | B1: Employee_Name | C1: Department | D1: Total_Points
A2: 450230 | B2: =IFERROR(VLOOKUP(A2,Employee_Master!A:B,2,0),"") -> Aarti Gupta | C2: =IFERROR(VLOOKUP(A2,Employee_Master!A:B,3,0),"") | D2: =IF(SUMIF(Participation_Entry!B:B,A2,Participation_Entry!L:L)=0,"",SUMIF(Participation_Entry!B:B,A2,Participation_Entry!L:L)) -> 196.3525
A3: 452073 | B3: =IFERROR(VLOOKUP(A3,Employee_Master!A:B,2,0),"") -> Aashish | C3: =IFERROR(VLOOKUP(A3,Employee_Master!A:B,3,0),"") | D3: =IF(SUMIF(Participation_Entry!B:B,A3,Participation_Entry!L:L)=0,"",SUMIF(Participation_Entry!B:B,A3,Participation_Entry!L:L)) -> 108.2557
A4: 461161 | B4: =IFERROR(VLOOKUP(A4,Employee_Master!A:B,2,0),"") -> Abhay Singh | C4: =IFERROR(VLOOKUP(A4,Employee_Master!A:B,3,0),"") | D4: =IF(SUMIF(Participation_Entry!B:B,A4,Participation_Entry!L:L)=0,"",SUMIF(Participation_Entry!B:B,A4,Participation_Entry!L:L)) -> 77.2203
A5: 456091 | B5: =IFERROR(VLOOKUP(A5,Employee_Master!A:B,2,0),"") -> Abhinesh Pandey | C5: =IFERROR(VLOOKUP(A5,Employee_Master!A:B,3,0),"") | D5: =IF(SUMIF(Participation_Entry!B:B,A5,Participation_Entry!L:L)=0,"",SUMIF(Participation_Entry!B:B,A5,Participation_Entry!L:L)) -> 108.9789
A6: 478308 | B6: =IFERROR(VLOOKUP(A6,Employee_Master!A:B,2,0),"") -> Abhishek savita | C6: =IFERROR(VLOOKUP(A6,Employee_Master!A:B,3,0),"") | D6: =IF(SUMIF(Participation_Entry!B:B,A6,Participation_Entry!L:L)=0,"",SUMIF(Participation_Entry!B:B,A6,Participation_Entry!L:L)) -> 152.4722
A7: 478266 | B7: =IFERROR(VLOOKUP(A7,Employee_Master!A:B,2,0),"") -> Abhishek Sharma | C7: =IFERROR(VLOOKUP(A7,Employee_Master!A:B,3,0),"") | D7: =IF(SUMIF(Participation_Entry!B:B,A7,Participation_Entry!L:L)=0,"",SUMIF(Participation_Entry!B:B,A7,Participation_Entry!L:L)) -> 72.1534
A8: 466167 | B8: =IFERROR(VLOOKUP(A8,Employee_Master!A:B,2,0),"") -> Aishwarya Sharma | C8: =IFERROR(VLOOKUP(A8,Employee_Master!A:B,3,0),"") | D8: =IF(SUMIF(Participation_Entry!B:B,A8,Participation_Entry!L:L)=0,"",SUMIF(Participation_Entry!B:B,A8,Participation_Entry!L:L)) -> 269.4088
A9: 712428 | B9: =IFERROR(VLOOKUP(A9,Employee_Master!A:B,2,0),"") -> Akanksha Gangwar | C9: =IFERROR(VLOOKUP(A9,Employee_Master!A:B,3,0),"") | D9: =IF(SUMIF(Participation_Entry!B:B,A9,Participation_Entry!L:L)=0,"",SUMIF(Participation_Entry!B:B,A9,Participation_Entry!L:L)) -> 302.9128
A10: 454456 | B10: =IFERROR(VLOOKUP(A10,Employee_Master!A:B,2,0),"") -> Akash Deshmukh | C10: =IFERROR(VLOOKUP(A10,Employee_Master!A:B,3,0),"") | D10: =IF(SUMIF(Participation_Entry!B:B,A10,Participation_Entry!L:L)=0,"",SUMIF(Participation_Entry!B:B,A10,Participation_Entry!L:L)) -> 198.7193
A11: 452119 | B11: =IFERROR(VLOOKUP(A11,Employee_Master!A:B,2,0),"") -> Akhil Tiwari | C11: =IFERROR(VLOOKUP(A11,Employee_Master!A:B,3,0),"") | D11: =IF(SUMIF(Participation_Entry!B:B,A11,Participation_Entry!L:L)=0,"",SUMIF(Participation_Entry!B:B,A11,Participation_Entry!L:L)) -> 153.378
A12: 430977 | B12: =IFERROR(VLOOKUP(A12,Employee_Master!A:B,2,0),"") -> Akshit Sood | C12: =IFERROR(VLOOKUP(A12,Employee_Master!A:B,3,0),"") | D12: =IF(SUMIF(Participation_Entry!B:B,A12,Participation_Entry!L:L)=0,"",SUMIF(Participation_Entry!B:B,A12,Participation_Entry!L:L)) -> 197.2518
A13: 451857 | B13: =IFERROR(VLOOKUP(A13,Employee_Master!A:B,2,0),"") -> Amar Kumar | C13: =IFERROR(VLOOKUP(A13,Employee_Master!A:B,3,0),"") | D13: =IF(SUMIF(Participation_Entry!B:B,A13,Participation_Entry!L:L)=0,"",SUMIF(Participation_Entry!B:B,A13,Participation_Entry!L:L)) -> 142.987
... A182: 726299 | B182: =IFERROR(VLOOKUP(A182,Employee_Master!A:B,2,0),"") -> Anu Devi | C182: =IFERROR(VLOOKUP(A182,Employee_Master!A:B,3,0),"") | D182: =IF(SUMIF(Participation_Entry!B:B,A182,Participation_Entry!L:L)=0,"",SUMIF(Participation_Entry!B:B,A182,Participation_Entry!L:L))

Sheet Schedule
A1: Event | B1: Start_Time
A2: Badminton Single | B2: 2026-03-06 15:30:00
A3: Badminton Single Girls | B3: 2026-03-06 15:30:00
A4: Table Tennis
A5: Walk
